package pointersanderrors

import "testing"

func TestWallet(t *testing.T) {
	assertBalance := func(t testing.TB, wallet Wallet, want Bitcoin) {
		t.Helper()
		got := wallet.Balance()

		if got != want {
			t.Errorf("got %s want %s", got, want)
		}
	}

	assertError := func(t testing.TB, got error, want error) {
		t.Helper()
		// t.Fatal will stop the test if it is called. This is because we don't want to make any more assertions on the error returned if there isn't one around
		if got == nil {
			t.Fatal("wanted an error but didn't get one")
		}

		if got != want {
			t.Errorf("got %q, want %q", got, want)
		}
	}

	t.Run("deposit", func(t *testing.T) {
		wallet := Wallet{}
		wallet.Deposit(Bitcoin(10))
		assertBalance(t, wallet, Bitcoin(10))

	})

	t.Run("withdraw", func(t *testing.T) {
		wallet := Wallet{balance: 20}
		err := wallet.Withdraw(Bitcoin(10))
		assertNoError(t, err)
		assertBalance(t, wallet, Bitcoin(10))
	})

	t.Run("withdraw insufficient funds", func(t *testing.T) {
		startingBalance := Bitcoin(20)
		wallet := Wallet{balance: startingBalance}
		err := wallet.Withdraw(Bitcoin(100))

		assertBalance(t, wallet, startingBalance)
		assertError(t, err, ErrInsufficientFunds)
	})
}

func assertNoError(t testing.TB, got error) {
	t.Helper()
	if got != nil {
		t.Fatal("got an error but didn't want one")
	}
}
